<?xml version="1.0" encoding="utf-8"?>
<!-- This URDF was automatically created by SolidWorks to URDF Exporter! Originally created by Stephen Brawner (brawner@gmail.com) 
     Commit Version: 1.6.0-1-g15f4949  Build Version: 1.6.7594.29634
     For more information, please see http://wiki.ros.org/sw_urdf_exporter -->
<robot
  name="spadS100">
  <link
    name="base_link">
    <inertial>
      <origin
        xyz="-0.143558743368683 4.16333634234434E-17 -0.000254295342407077"
        rpy="0 0 0" />
      <mass
        value="4.8826996293206" />
      <inertia
        ixx="0.0160147165797759"
        ixy="-1.49011876027327E-18"
        ixz="8.12027234175984E-06"
        iyy="0.0349824035670418"
        iyz="-3.77937683935304E-19"
        izz="0.0419769366326633" />
    </inertial>
    <visual>
      <origin
        xyz="0 0 0"
        rpy="0 0 0" />
      <geometry>
        <mesh
          filename="package://spadS100/meshes/base_link.STL" />
      </geometry>
      <material
        name="">
        <color
          rgba="0.792156862745098 0.819607843137255 0.933333333333333 1" />
      </material>
    </visual>
    <collision>
      <origin
        xyz="0 0 0"
        rpy="0 0 0" />
      <geometry>
        <mesh
          filename="package://spadS100/meshes/base_link.STL" />
      </geometry>
    </collision>
  </link>
  <link
    name="Link1">
    <inertial>
      <origin
        xyz="0.0243203705649345 -0.000484902606538731 0.0390507650880949"
        rpy="0 0 0" />
      <mass
        value="0.110864751991613" />
      <inertia
        ixx="4.13225088702076E-05"
        ixy="-3.88360572701108E-07"
        ixz="-2.24588708689794E-05"
        iyy="6.37243973387624E-05"
        iyz="-3.25817231944212E-07"
        izz="4.91046991336971E-05" />
    </inertial>
    <visual>
      <origin
        xyz="0 0 0"
        rpy="0 0 0" />
      <geometry>
        <mesh
          filename="package://spadS100/meshes/Link1.STL" />
      </geometry>
      <material
        name="">
        <color
          rgba="0.752941176470588 0.752941176470588 0.752941176470588 1" />
      </material>
    </visual>
    <collision>
      <origin
        xyz="0 0 0"
        rpy="0 0 0" />
      <geometry>
        <mesh
          filename="package://spadS100/meshes/Link1.STL" />
      </geometry>
    </collision>
  </link>
  <joint
    name="joint1"
    type="continuous">
    <origin
      xyz="-0.06 0 0.0525"
      rpy="0 0 0" />
    <parent
      link="base_link" />
    <child
      link="Link1" />
    <axis
      xyz="0 0 1" />
  </joint>
  <link
    name="Link2">
    <inertial>
      <origin
        xyz="0.00955656672573496 0.02959921850808 0.00366631668138551"
        rpy="0 0 0" />
      <mass
        value="0.0232388450514006" />
      <inertia
        ixx="1.2972096565915E-05"
        ixy="-3.68804276703001E-06"
        ixz="8.7216944804824E-23"
        iyy="2.73999302404856E-06"
        iyz="-4.20066383093746E-22"
        izz="1.56558569465794E-05" />
    </inertial>
    <visual>
      <origin
        xyz="0 0 0"
        rpy="0 0 0" />
      <geometry>
        <mesh
          filename="package://spadS100/meshes/Link2.STL" />
      </geometry>
      <material
        name="">
        <color
          rgba="0.752941176470588 0.752941176470588 0.752941176470588 1" />
      </material>
    </visual>
    <collision>
      <origin
        xyz="0 0 0"
        rpy="0 0 0" />
      <geometry>
        <mesh
          filename="package://spadS100/meshes/Link2.STL" />
      </geometry>
    </collision>
  </link>
  <joint
    name="joint"
    type="continuous">
    <origin
      xyz="0.042174 0 0.054422"
      rpy="1.5708 0 0" />
    <parent
      link="Link1" />
    <child
      link="Link2" />
    <axis
      xyz="0 0 1" />
  </joint>
  <link
    name="Link3">
    <inertial>
      <origin
        xyz="0.0479706059601693 -0.0016736097682499 -0.00147608993815138"
        rpy="0 0 0" />
      <mass
        value="0.151265370497947" />
      <inertia
        ixx="2.56860118101981E-05"
        ixy="3.20823747815898E-06"
        ixz="9.13592476565545E-11"
        iyy="0.00011943489198943"
        iyz="-1.2217449448932E-10"
        izz="0.000115105559620247" />
    </inertial>
    <visual>
      <origin
        xyz="0 0 0"
        rpy="0 0 0" />
      <geometry>
        <mesh
          filename="package://spadS100/meshes/Link3.STL" />
      </geometry>
      <material
        name="">
        <color
          rgba="0.752941176470588 0.752941176470588 0.752941176470588 1" />
      </material>
    </visual>
    <collision>
      <origin
        xyz="0 0 0"
        rpy="0 0 0" />
      <geometry>
        <mesh
          filename="package://spadS100/meshes/Link3.STL" />
      </geometry>
    </collision>
  </link>
  <joint
    name="joint3"
    type="continuous">
    <origin
      xyz="0.022122 0.068517 0"
      rpy="0 0 0" />
    <parent
      link="Link2" />
    <child
      link="Link3" />
    <axis
      xyz="0 0 -1" />
  </joint>
  <link
    name="Link4">
    <inertial>
      <origin
        xyz="0.102122099305755 0.0351858704393887 0.00906682979334579"
        rpy="0 0 0" />
      <mass
        value="0.0879227358363708" />
      <inertia
        ixx="1.94634770429794E-05"
        ixy="-7.02902732549627E-06"
        ixz="1.63552624920972E-08"
        iyy="4.38071865969415E-05"
        iyz="-7.4493280138576E-08"
        izz="4.29126286227738E-05" />
    </inertial>
    <visual>
      <origin
        xyz="0 0 0"
        rpy="0 0 0" />
      <geometry>
        <mesh
          filename="package://spadS100/meshes/Link4.STL" />
      </geometry>
      <material
        name="">
        <color
          rgba="0.752941176470588 0.752941176470588 0.752941176470588 1" />
      </material>
    </visual>
    <collision>
      <origin
        xyz="0 0 0"
        rpy="0 0 0" />
      <geometry>
        <mesh
          filename="package://spadS100/meshes/Link4.STL" />
      </geometry>
    </collision>
  </link>
  <joint
    name="joint4"
    type="continuous">
    <origin
      xyz="0.095944 -0.0032792 0"
      rpy="0 0 0" />
    <parent
      link="Link3" />
    <child
      link="Link4" />
    <axis
      xyz="0 0 -1" />
  </joint>
</robot>